Workbook

Sheet Concepts
A1: Status | B1: Praxis ID | C1: Canonical Name | D1: Tier | E1: Primary Domain | F1: Type | G1: Legacy Type | H1: Tradition | I1: Origin | J1: Date | K1: Difficulty | L1: Evidence | M1: One Sentence | N1: Story | O1: Definition | P1: Mechanism (ordered chain) | Q1: Common Misconception | R1: Nearest Neighbour | S1: Discriminate Scenario | T1: Praxis Exercise | U1: Identity Tags | V1: Related Concepts | W1: Book IDs | X1: Author | Y1: Notes
A2: Done | B2: 01.01 | C2: First Principles Thinking | D2: Integration | E2: Reasoning & Sensemaking | F2: Mental Model | G2: Mental Model | H2: Reasoning / Philosophy | I2: Rene Descartes | J2: 1637 | K2: Introductory | L2: Framework | M2: Break a problem down to what you know is true, then rebuild from there. | O2: Reasoning from foundational truths rather than by analogy to how things are already done. Descartes resolved to doubt everything he could and rebuild only on what survived the doubting. The move is to strip a problem back to the things you can actually defend, then reason forward from those alone. | P2: inherited assumption -> unexamined constraint -> only incremental improvement stripped to fundamentals -> constraints tested -> solutions convention was hiding | Q2: "It means ignoring what everyone else does." It does not require discarding convention. It requires knowing which parts of it are load-bearing. Most conventions encode a real constraint; the work is separating those from the ones that merely persist. | R2: CHESTERTON'S FENCE. That one warns you not to remove a convention until you understand why it exists. This one is the method for examining it. They pull in opposite directions and are strongest used together. | S2: A caterer prices every job at twice her ingredient cost, because that is what her old employer did. When a large order loses money she sits down and works out what actually drives her costs, and finds that labour, not ingredients, is the thing her pricing should have been tracking all along. | T2: STRIP IT DOWN 1. Name one rule you follow in your work. 2. Write down why you believe it is true. 3. For each reason ask: do I know this, or did I inherit it? 4. Keep only what you can defend, and rebuild the rule from those parts. COMMITMENT (if-then): "When I catch myself saying this is how it is done, I will write down what I actually know to be true before going further." | U2: Clear thinker | V2: Inversion | W2: BK030 | X2: Claude draft, needs Lindsay review
A3: Done | B3: 01.02 | C3: Inversion | D3: Integration | E3: Reasoning & Sensemaking | F3: Mental Model | G3: Mental Model | H3: Decision Theory / Practical Reasoning | I3: Carl Jacobi, popularised by Charlie Munger | J3: 2005 | K3: Introductory | L3: Framework | M3: Solve a problem backwards by asking what would guarantee failure. | O3: Rather than asking how to succeed, you ask how you would reliably fail, then remove those conditions. Attributed to the mathematician Carl Jacobi, who advised inverting difficult problems, and made a standing habit of thought by Charlie Munger. | P3: forward question -> vague aspirational answers -> nothing to act on inverted question -> concrete failure conditions -> specific behaviours to remove | Q3: "Inversion is just negative thinking." It is not pessimism. Failure conditions are simply easier to name precisely than success conditions, which is why inverting produces a list you can act on where the forward question produces platitudes. | R3: PREMORTEM. That one imagines a particular project has already failed and asks why. This is the general move of flipping any question on its head; the premortem is one applied instance of it. | S3: Tom wants to write a book and keeps making plans that go nowhere. A friend asks him instead to list everything he could do to make sure he never finishes it. He names four things straight away, realises he is already doing three of them, and stops one that week. | T3: FAILURE AUDIT 1. Choose one goal you currently care about. 2. Ask: how could I guarantee failure here? 3. List five behaviours that would make failure likely. 4. Mark the ones you are already doing. 5. Remove one of them this week. COMMITMENT (if-then): "When I set a goal, I will write the five ways I could guarantee failure before I write any plan." | U3: Clear thinker; Disciplined | V3: First Principles Thinking; Premortem | W3: BK059 | X3: Claude draft, needs Lindsay review
A4: Stub | B4: 01.03 | C4: Occam’s Razor | D4: Integration | E4: Reasoning & Sensemaking | F4: Heuristic | G4: Heuristic | H4: Philosophy of Science / Logic | U4: Clear thinker | W4: BK109
A5: Stub | B5: 01.04 | C5: Hanlon’s Razor | D5: Integration | E5: Reasoning & Sensemaking | F5: Heuristic | G5: Heuristic | H5: Practical Reasoning | U5: Clear thinker; Emotionally regulated | W5: BK096
A6: Stub | B6: 01.05 | C6: Chesterton’s Fence | D6: Integration | E6: Reasoning & Sensemaking | F6: Mental Model | G6: Mental Model | H6: Political Philosophy / Institutional Reasoning | U6: Clear thinker; High integrity | W6: BK120
A7: Stub | B7: 01.06 | C7: The Map Is Not the Territory | D7: Integration | E7: Reasoning & Sensemaking | F7: Mental Model | G7: Mental Model | H7: General Semantics / Epistemology | U7: Clear thinker | W7: BK067
A8: Stub | B8: 01.07 | C8: Falsifiability | D8: Integration | E8: Reasoning & Sensemaking | F8: Philosophical Principle | G8: Epistemic Principle | H8: Philosophy of Science | U8: Clear thinker | W8: BK003; BK109
A9: Stub | B9: 01.08 | C9: Burden of Proof | D9: Integration | E9: Reasoning & Sensemaking | F9: Influence Principle | G9: Argumentation Principle | H9: Logic / Argumentation | U9: Clear thinker; Manipulation proof | W9: BK087
A10: Done | B10: 01.09 | C10: Principle of Charity | D10: Integration | E10: Reasoning & Sensemaking | F10: Influence Principle | G10: Argumentation Principle | H10: Philosophy / Argumentation | I10: Neil Wilson and Donald Davidson | J10: 1959 | K10: Introductory | L10: Philosophical | M10: Interpreting what someone said in its strongest reasonable sense. | O10: A principle of interpretation holding that when a statement admits of several readings, you should engage the one that is most coherent and most likely to be meant. It is not generosity for its own sake. A weak reading of an argument tells you nothing about whether the argument is any good, so charity is a condition of learning anything from disagreement. | P10: you take the weakest available reading -> you refute something nobody argued -> you learn nothing and they do not change you take the strongest reading -> you engage the real claim -> either you are changed or they are | Q10: "Being charitable means agreeing more, or being soft on bad arguments." It makes criticism harder to escape, not softer. Refuting the strongest version is a far more serious challenge than refuting a sloppy one, and the person cannot reply that you misunderstood them. | R10: STEELMANNING. That goes a step further and improves the argument beyond what was actually said, constructing the best possible case. Charity stays within what the person plausibly meant. One is accurate interpretation, the other is active reconstruction. | S10: In a thread about remote work, someone writes that offices help junior staff. A reply treats this as a claim that everyone must return five days a week, and knocks it down easily. The original poster never meant that, and the exchange ends with both sides more certain than before. | T10: THE BEST READING 1. Find something you disagreed with this week, in writing. 2. Write the reading of it you reacted to. 3. Write the strongest reading it could bear. 4. Decide whether your objection still holds against the second one. COMMITMENT (if then): "When I am about to disagree in writing, I will write the strongest version of their point first and check my objection against that." | U10: Clear thinker; Clear communicator; High integrity | V10: Steelmanning; Straw Man Fallacy | W10: BK022 | X10: Claude draft, needs Lindsay review
A11: Done | B11: 01.10 | C11: Steelmanning | D11: Integration | E11: Reasoning & Sensemaking | F11: Influence Principle | G11: Argumentation Technique | H11: Argumentation / Debate | I11: Attributed to Daniel Dennett and others | J11: 2013 | K11: Intermediate | L11: Framework | M11: Building the strongest version of an argument before you take it apart. | O11: A practice of constructing the best case for a position, including improvements its actual defenders have not made, and then responding to that. Where charity asks you to read fairly, steelmanning asks you to build. Its purpose is partly honesty and partly self interest, because an objection that only defeats a weak version has told you nothing about whether you are right. | P11: you argue against what was said -> any weakness in their phrasing does your work for you -> your own position is never tested you argue against the strongest possible version -> their phrasing is no longer the weak point -> you find out whether you are actually right | Q11: "Steelmanning is a debate tactic for looking fair minded." If it is performed rather than done, it is worthless. The point is private, not social: you build the strong version in order to find out whether your own view survives it, and sometimes it does not. | R11: PRINCIPLE OF CHARITY. That asks you to interpret what was said in its strongest reasonable sense, staying within what the person meant. This goes beyond them, improving the argument past anything they said. Charity is about accuracy, this is about construction. | S11: Before writing a piece arguing against a popular productivity method, Nadia spends an afternoon writing the best case for it she can manage. Two of her four objections do not survive the exercise. The piece she eventually publishes makes the remaining two, and is far harder to dismiss. | T11: BUILD IT FIRST 1. Take a position you argue against. 2. Write the best case for it you can, including points its defenders usually miss. 3. Show it to someone who holds that view and ask what you left out. 4. Now write your objection, against that version. COMMITMENT (if then): "When I plan to argue against something publicly, I will write its strongest case first and check which of my objections survive." | U11: Clear thinker; Clear communicator | V11: Principle of Charity; Straw Man Fallacy | W11: BK022 | X11: Claude draft, needs Lindsay review
A12: Done | B12: 01.11 | C12: Straw Man Fallacy | D12: Integration | E12: Reasoning & Sensemaking | F12: Fallacy | G12: Fallacy | H12: Informal Logic | I12: Classical informal logic | K12: Introductory | L12: Philosophical | M12: Refuting a distorted version of an argument instead of the real one. | O12: An error of reasoning in which a position is restated in a weakened or exaggerated form, and the weakened form is then defeated. The appearance of victory comes from the substitution, not from the argument. It is often unintentional, since the distorted version is usually the one that felt easiest to answer. | P12: real claim is hard to answer -> a simpler version comes to mind -> the simpler version is attacked -> the original claim stands untouched | Q12: "A straw man is just any unfair characterisation of someone's view." Unfairness alone is not enough. The error is specifically substituting a weaker claim and then treating its defeat as a defeat of the original. Describing someone's view rudely but accurately is not this. | R12: MOTTE AND BAILEY. That is the mirror image, where a speaker defends a modest claim and then behaves as though a far bolder one had been established. One distorts the opponent's position downward, the other shifts one's own position back and forth. | S12: A councillor proposes reducing the speed limit on two residential streets. At the public meeting a resident stands up to say that banning cars from the town centre would destroy local business, and sits down to applause. The speed limit proposal is never discussed. | T12: FIND THE SUBSTITUTION 1. Recall an argument you felt you won easily. 2. Write what you argued against. 3. Write what they actually claimed, in their words if you have them. 4. If the two differ, your win was against something you built. COMMITMENT (if then): "When an opposing argument feels easy to defeat, I will check their actual words before replying." | U12: Clear thinker; Manipulation proof; Clear communicator | V12: Principle of Charity; Steelmanning | W12: BK014 | X12: Claude draft, needs Lindsay review
A13: Stub | B13: 01.12 | C13: Ad Hominem Fallacy | D13: Integration | E13: Reasoning & Sensemaking | F13: Fallacy | G13: Fallacy | H13: Informal Logic | U13: Clear thinker; Manipulation proof | W13: BK005
A14: Stub | B14: 01.13 | C14: False Dilemma | D14: Integration | E14: Reasoning & Sensemaking | F14: Fallacy | G14: Fallacy | H14: Informal Logic | U14: Clear thinker; Manipulation proof | W14: BK014
A15: Stub | B15: 01.14 | C15: Slippery Slope | D15: Integration | E15: Reasoning & Sensemaking | F15: Fallacy | G15: Fallacy | H15: Informal Logic | U15: Clear thinker; Manipulation proof | W15: BK070
A16: Stub | B16: 01.15 | C16: Appeal to Authority | D16: Integration | E16: Reasoning & Sensemaking | F16: Fallacy | G16: Fallacy | H16: Informal Logic / Epistemology | U16: Clear thinker; Manipulation proof | W16: BK008
A17: Stub | B17: 01.16 | C17: Appeal to Popularity | D17: Integration | E17: Reasoning & Sensemaking | F17: Fallacy | G17: Fallacy | H17: Informal Logic / Social Psychology | U17: Clear thinker; Manipulation proof | W17: BK121
A18: Stub | B18: 01.17 | C18: Appeal to Ignorance | D18: Integration | E18: Reasoning & Sensemaking | F18: Fallacy | G18: Fallacy | H18: Informal Logic | U18: Clear thinker; Manipulation proof | W18: BK010
A19: Stub | B19: 01.18 | C19: Circular Reasoning | D19: Integration | E19: Reasoning & Sensemaking | F19: Fallacy | G19: Fallacy | H19: Formal / Informal Logic | U19: Clear thinker; Manipulation proof | W19: BK015
A20: Stub | B20: 01.19 | C20: Red Herring | D20: Integration | E20: Reasoning & Sensemaking | F20: Fallacy | G20: Fallacy | H20: Argumentation / Rhetoric | U20: Clear thinker; Manipulation proof | W20: BK087
A21: Stub | B21: 01.20 | C21: Equivocation | D21: Integration | E21: Reasoning & Sensemaking | F21: Fallacy | G21: Fallacy | H21: Logic / Linguistics | U21: Clear thinker; Manipulation proof | W21: BK044
A22: Stub | B22: 01.21 | C22: Genetic Fallacy | D22: Integration | E22: Reasoning & Sensemaking | F22: Fallacy | G22: Fallacy | H22: Informal Logic | U22: Clear thinker; Manipulation proof | W22: BK014
A23: Stub | B23: 01.22 | C23: No True Scotsman | D23: Integration | E23: Reasoning & Sensemaking | F23: Fallacy | G23: Fallacy | H23: Informal Logic | U23: Clear thinker; Manipulation proof | W23: BK127
A24: Stub | B24: 01.23 | C24: Moving the Goalposts | D24: Integration | E24: Reasoning & Sensemaking | F24: Fallacy | G24: Fallacy | H24: Argumentation | U24: Clear thinker; Manipulation proof | W24: BK011
... A31: Stub | B31: 02.05 | C31: Base-Rate Neglect | D31: Integration | E31: Decisions & Risk | F31: Cognitive Bias | G31: Cognitive Bias | H31: Cognitive Psychology / Behavioral Decision Science | U31: Sound judgement | W31: BK061; BK128
A32: Done | B32: 02.06 | C32: Sunk-Cost Fallacy | D32: Integration | E32: Decisions & Risk | F32: Cognitive Bias | G32: Cognitive Bias | H32: Behavioral Economics / Decision Science | I32: Hal Arkes and Catherine Blumer | J32: 1985 | K32: Introductory | L32: Replicated | M32: Carrying on with something because of what you already spent on it. | O32: A sunk cost is a cost already paid that cannot be recovered. The fallacy is letting it influence a decision about the future. Rationally, only the costs and benefits still ahead of you should count; in practice, what has already gone in exerts a strong pull toward continuing. | P32: resources already committed -> continuing feels like recovering them -> quitting feels like admitting waste -> the decision is made on the past rather than the future | Q32: "It means you should quit things easily." It does not. Plenty of commitments are worth continuing on their own merits. The fallacy is specifically about using past expenditure as the reason, rather than whether the thing is still worth doing from here. | R32: LOSS AVERSION. That one is the general tendency to feel losses more sharply than equivalent gains. Sunk cost is a specific decision error that loss aversion helps explain. You can be loss averse without committing the fallacy, and the fallacy also draws on a reluctance to look inconsistent. | S32: Elena is two years into a qualification she no longer wants, in a field she has decided against. Every time she considers stopping, she thinks about the fees and the evenings already spent. She signs up for another year, and cannot say what the qualification will actually get her. | T32: THE FRESH START TEST 1. Name a commitment you are unsure about. 2. Ask: if I were arriving at this today, with none of the history, would I choose it? 3. If no, write what is actually keeping you in it. 4. Separate the reasons that look forward from the ones that look back. COMMITMENT (if-then): "When I notice I am justifying something by what I have already put in, I will ask what I would choose if I were starting from today." | U32: Sound judgement; Disciplined | V32: Loss Aversion; Opportunity Cost | W32: BK026; BK061 | X32: Claude draft, needs Lindsay review
A33: Stub | B33: 02.07 | C33: Loss Aversion | D33: Integration | E33: Decisions & Risk | F33: Cognitive Bias | G33: Cognitive Bias | H33: Behavioral Economics | U33: Sound judgement; Emotionally regulated | W33: BK061
A34: Stub | B34: 02.08 | C34: Anchoring | D34: Integration | E34: Decisions & Risk | F34: Cognitive Bias | G34: Cognitive Bias | H34: Behavioral Economics / Cognitive Psychology | U34: Sound judgement; Manipulation proof | W34: BK061
A35: Stub | B35: 02.09 | C35: Framing Effect | D35: Integration | E35: Decisions & Risk | F35: Cognitive Bias | G35: Cognitive Bias | H35: Behavioral Economics / Cognitive Psychology | U35: Sound judgement; Manipulation proof | W35: BK026; BK061
A36: Stub | B36: 02.10 | C36: Availability Heuristic | D36: Integration | E36: Decisions & Risk | F36: Cognitive Bias | G36: Heuristic / Bias | H36: Cognitive Psychology | U36: Sound judgement | W36: BK128
A37: Stub | B37: 02.11 | C37: Representativeness Heuristic | D37: Integration | E37: Decisions & Risk | F37: Cognitive Bias | G37: Heuristic / Bias | H37: Cognitive Psychology | U37: Sound judgement | W37: BK128
A38: Stub | B38: 02.12 | C38: Status-Quo Bias | D38: Integration | E38: Decisions & Risk | F38: Cognitive Bias | G38: Cognitive Bias | H38: Behavioral Economics | U38: Sound judgement; Disciplined | W38: BK026; BK061
A39: Stub | B39: 02.13 | C39: Endowment Effect | D39: Integration | E39: Decisions & Risk | F39: Cognitive Bias | G39: Cognitive Bias | H39: Behavioral Economics | U39: Sound judgement | W39: BK061
A40: Stub | B40: 02.14 | C40: Survivorship Bias | D40: Integration | E40: Decisions & Risk | F40: Cognitive Bias | G40: Cognitive Bias | H40: Decision Science / Statistics | U40: Sound judgement | W40: BK007; BK128
A41: Stub | B41: 02.15 | C41: Present Bias | D41: Integration | E41: Decisions & Risk | F41: Cognitive Bias | G41: Cognitive Bias | H41: Behavioral Economics / Decision Science | U41: Disciplined; Self-authoring | W41: BK012; BK061
A42: Stub | B42: 02.16 | C42: Affect Heuristic | D42: Integration | E42: Decisions & Risk | F42: Cognitive Bias | G42: Heuristic / Bias | H42: Cognitive Psychology / Risk Perception | U42: Sound judgement; Emotionally regulated | W42: BK128
A43: Stub | B43: 02.17 | C43: Outcome Bias | D43: Integration | E43: Decisions & Risk | F43: Cognitive Bias | G43: Cognitive Bias | H43: Decision Science | U43: Sound judgement | W43: BK128
A44: Stub | B44: 02.18 | C44: Hindsight Bias | D44: Integration | E44: Decisions & Risk | F44: Cognitive Bias | G44: Cognitive Bias | H44: Cognitive Psychology / Decision Science | U44: Sound judgement | W44: BK128
... A63: Stub | B63: 03.12 | C63: Rationalization | D63: Integration | E63: Self-Knowledge & Behaviour | F63: Defense Mechanism | G63: Defense Mechanism | H63: Psychodynamic Psychology / Social Psychology | U63: Self-authoring; Clear thinker | W63: BK090; BK099
A64: Done | B64: 03.13 | C64: Solomon’s Paradox | D64: Integration | E64: Self-Knowledge & Behaviour | F64: Paradox | G64: Psychological Effect / Paradox | H64: Social Psychology / Wisdom Research | I64: Igor Grossmann and Ethan Kross | J64: 2014 | K64: Introductory | L64: Supported | M64: We reason more wisely about other people's problems than our own. | O64: Named for King Solomon, who counselled others wisely but governed his own household badly. Grossmann and Kross found that people reason about their own problems with measurably less wisdom, by which is meant acknowledging the limits of what they know, allowing for change, weighing other perspectives and seeking compromise, than about an identical problem belonging to someone else. | P64: my problem -> high emotional proximity -> narrowed perspective -> poorer reasoning someone else's problem -> psychological distance -> broader perspective -> wiser reasoning | Q64: "People are just smarter about other people's lives." The effect is not about intelligence, and not about caring less. The same person, with the same intelligence, reasons worse on their own problem. The variable is distance, not ability, which is why manufacturing distance artificially reverses the effect. | R64: ACTOR-OBSERVER BIAS. That one is about attribution: we explain our own behaviour by circumstance and other people's by character. This is about the quality of reasoning itself, not about who gets blamed. A person can show either one without the other. | S64: Maya tells her friend, without hesitating, that she should leave a relationship in which she is constantly let down. Six months later Maya is in a near-identical situation and finds herself explaining why this time the circumstances are different, and why leaving now would be premature. | T64: THE OUTSIDER TEST 1. Choose one unresolved problem currently affecting you. 2. Write it in the third person: "[Name] has been struggling with..." 3. Answer as though advising your closest friend: - What would you tell her? - What is she failing to see? - What is she treating as certain that is not? - Whose perspective has she not considered? - What might look different in six months? 4. Return to the first person: what advice still applies to you? COMMITMENT (if-then): "When I notice I am emotionally invested in a decision, I will write the problem in the third person before deciding anything." | U64: Clear thinker; Self-authoring; Emotionally regulated | V64: Actor Observer Bias; Cognitive Reappraisal | W64: BK019 | X64: Claude draft, needs Lindsay review
...

Sheet Sheet

Sheet Vocabulary
A1: Domains | B1: Types | C1: Identities | D1: Difficulty | E1: Tier | F1: Status | G1: Evidence | H1: What it means
A2: Communication & Influence | B2: Archetype | C2: Clear thinker | D2: Introductory | E2: Discovery | F2: Stub | G2: Replicated | H2: A robust empirical finding that holds up across independent studies
A3: Creativity, Craft & Mastery | B3: Attachment Pattern | C3: Disciplined | D3: Intermediate | E3: Integration | F3: Drafted | G3: Supported | H3: Real research behind it, but less settled or narrower than replicated
A4: Decisions & Risk | B4: Behavioural Principle | C4: Clear communicator | D4: Advanced | F4: In review | G4: Contested | H4: Widely used and widely taught, but the evidence is disputed
A5: Human Nature & Social Behaviour | B5: Cognitive Bias | C5: Emotionally regulated | F5: Done | G5: Framework | H5: A way of organising thinking. Useful or not, rather than true or false
A6: Learning, Memory & Attention | B6: Communication Principle | C6: Manipulation proof | G6: Philosophical | H6: An argument or position, not an empirical claim
A7: Meaning, Ethics & Philosophy | B7: Creativity Concept | C7: High integrity | G7: Traditional | H7: From a wisdom, mythic or religious tradition
A8: Myth, Symbol & Spiritual Traditions | B8: Decision Model | C8: Creatively unblocked
A9: Power, Strategy & Conflict | B9: Defense Mechanism | C9: Self-authoring
A10: Reasoning & Sensemaking | B10: Economic Concept | C10: Sound judgement
A11: Relationships & Attraction | B11: Ethical Principle | C11: Systems literate
A12: Self-Knowledge & Behaviour | B12: Expertise Concept
A13: Society, Culture & Systems | B13: Fallacy
B14: Game-Theory Concept
B15: Heuristic
B16: Influence Principle
B17: Jungian Concept
B18: Learning Principle
B19: Mental Model
B20: Motivation Theory
B21: Mythic Concept
B22: Paradox
B23: Philosophical Principle
B24: Power Framework
B25: Psychological Effect
... B32: Practice
A34: Domains are your existing twelve, straight from the live site, at 25 concepts each. Do not add a thirteenth without deciding what it does to that balance. Types were 130+ distinct strings in the live data ('Psychological Effect' vs 'Psychological Effect / Paradox' vs 'Psychological Concept'). They are consolidated here to 29. Each concept's original string is preserved in the Legacy Type column on the Concepts sheet, so nothing is lost, but the Type column is what the site should use. Tradition is deliberately NOT validated: the live data has 197 distinct values across 300 concepts. Cleaning that up is its own pass, and it does not block anything.

Sheet Books
A1: Book ID | B1: Title | C1: Author | D1: Year | E1: Summary status | F1: One-line take | G1: Concepts linked | H1: Notes
A2: BK001 | B2: 48 Laws of Power | C2: Robert Greene | G2: =COUNTIF(Concepts!$U$2:$U$400,"*"&$A2&"*") -> 0
A3: BK002 | B3: A Guide to the Good Life | C3: William B. Irvine | G3: =COUNTIF(Concepts!$U$2:$U$400,"*"&$A3&"*") -> 0
A4: BK003 | B4: A History of Western Philosophy | C4: Bertrand Russell | G4: =COUNTIF(Concepts!$U$2:$U$400,"*"&$A4&"*") -> 0
A5: BK004 | B5: A Mind for Numbers | C5: Barbara Oakley | D5: 2014 | G5: =COUNTIF(Concepts!$U$2:$U$400,"*"&$A5&"*") -> 0
A6: BK005 | B6: Ad Hominem Arguments | C6: Douglas Walton | D6: 1998 | G6: =COUNTIF(Concepts!$U$2:$U$400,"*"&$A6&"*") -> 0
A7: BK006 | B7: Anatomy of Love | C7: Helen Fisher | G7: =COUNTIF(Concepts!$U$2:$U$400,"*"&$A7&"*") -> 0
A8: BK007 | B8: Antifragile | C8: Nassim Nicholas Taleb | G8: =COUNTIF(Concepts!$U$2:$U$400,"*"&$A8&"*") -> 0
A9: BK008 | B9: Appeal to Expert Opinion | C9: Douglas Walton | D9: 1997 | G9: =COUNTIF(Concepts!$U$2:$U$400,"*"&$A9&"*") -> 0
A10: BK009 | B10: Applied Economics | C10: Thomas Sowell | G10: =COUNTIF(Concepts!$U$2:$U$400,"*"&$A10&"*") -> 0
A11: BK010 | B11: Arguments from Ignorance | C11: Douglas Walton | D11: 1996 | G11: =COUNTIF(Concepts!$U$2:$U$400,"*"&$A11&"*") -> 0
A12: BK011 | B12: Asking the Right Questions | C12: M. Neil Browne & Stuart M. Keeley | D12: 1981 | G12: =COUNTIF(Concepts!$U$2:$U$400,"*"&$A12&"*") -> 0
A13: BK012 | B13: Atomic Habits | C13: James Clear | G13: =COUNTIF(Concepts!$U$2:$U$400,"*"&$A13&"*") -> 0
A14: BK013 | B14: Attached | C14: Amir Levine & Rachel Heller | G14: =COUNTIF(Concepts!$U$2:$U$400,"*"&$A14&"*") -> 0
A15: BK014 | B15: Attacking Faulty Reasoning | C15: T. Edward Damer | D15: 1980 | G15: =COUNTIF(Concepts!$U$2:$U$400,"*"&$A15&"*") -> 0
A16: BK015 | B16: Begging the Question | C16: Douglas Walton | D16: 1991 | G16: =COUNTIF(Concepts!$U$2:$U$400,"*"&$A16&"*") -> 0
A17: BK016 | B17: Big Magic | C17: Elizabeth Gilbert | G17: =COUNTIF(Concepts!$U$2:$U$400,"*"&$A17&"*") -> 0
A18: BK017 | B18: Boyd: The Fighter Pilot Who Changed the Art of War | C18: Robert Coram | D18: 2002 | G18: =COUNTIF(Concepts!$U$2:$U$400,"*"&$A18&"*") -> 0
A19: BK018 | B19: Captivate | C19: Vanessa Van Edwards | G19: =COUNTIF(Concepts!$U$2:$U$400,"*"&$A19&"*") -> 0
A20: BK019 | B20: Chatter | C20: Ethan Kross | D20: 2021 | G20: =COUNTIF(Concepts!$U$2:$U$400,"*"&$A20&"*") -> 0
A21: BK020 | B21: Compelling People | C21: John Neffinger & Matthew Kohut | G21: =COUNTIF(Concepts!$U$2:$U$400,"*"&$A21&"*") -> 0
A22: BK021 | B22: Creative Cognition: Theory, Research, and Applications | C22: Ronald A. Finke, Thomas B. Ward & Steven M. Smith | D22: 1992 | G22: =COUNTIF(Concepts!$U$2:$U$400,"*"&$A22&"*") -> 0
A23: BK022 | B23: Crucial Conversations | C23: Kerry Patterson, Joseph Grenny, Ron McMillan & Al Switzler | G23: =COUNTIF(Concepts!$U$2:$U$400,"*"&$A23&"*") -> 0
A24: BK023 | B24: Curious | C24: Ian Leslie | D24: 2014 | G24: =COUNTIF(Concepts!$U$2:$U$400,"*"&$A24&"*") -> 0
A25: BK024 | B25: Daily Rituals | C25: Mason Currey | G25: =COUNTIF(Concepts!$U$2:$U$400,"*"&$A25&"*") -> 0
A26: BK025 | B26: Debt: The First 5000 Years | C26: David Graeber | G26: =COUNTIF(Concepts!$U$2:$U$400,"*"&$A26&"*") -> 0
A27: BK026 | B27: Decisive | C27: Chip Heath & Dan Heath | G27: =COUNTIF(Concepts!$U$2:$U$400,"*"&$A27&"*") -> 0
A28: BK027 | B28: Deep Work | C28: Cal Newport | D28: 2016 | G28: =COUNTIF(Concepts!$U$2:$U$400,"*"&$A28&"*") -> 0
A29: BK028 | B29: Diffusion of Innovations | C29: Everett M. Rogers | D29: 1962 | G29: =COUNTIF(Concepts!$U$2:$U$400,"*"&$A29&"*") -> 0
A30: BK029 | B30: Discipline Is Destiny | C30: Ryan Holiday | G30: =COUNTIF(Concepts!$U$2:$U$400,"*"&$A30&"*") -> 0
A31: BK030 | B31: Discourse on the Method | C31: René Descartes | D31: 1637 | G31: =COUNTIF(Concepts!$U$2:$U$400,"*"&$A31&"*") -> 0
A32: BK031 | B32: Drive | C32: Daniel H. Pink | G32: =COUNTIF(Concepts!$U$2:$U$400,"*"&$A32&"*") -> 0
A33: BK032 | B33: Emotional Intelligence 2.0 | C33: Travis Bradberry & Jean Greaves | G33: =COUNTIF(Concepts!$U$2:$U$400,"*"&$A33&"*") -> 0
A34: BK033 | B34: Flourish | C34: Martin E. P. Seligman | D34: 2011 | G34: =COUNTIF(Concepts!$U$2:$U$400,"*"&$A34&"*") -> 0
A35: BK034 | B35: Foolproof: Why Misinformation Infects Our Minds and How to Build Immunity | C35: Sander van der Linden | D35: 2023 | G35: =COUNTIF(Concepts!$U$2:$U$400,"*"&$A35&"*") -> 0
A36: BK035 | B36: Freakonomics | C36: Steven D. Levitt & Stephen J. Dubner | G36: =COUNTIF(Concepts!$U$2:$U$400,"*"&$A36&"*") -> 0
A37: BK036 | B37: Give and Take | C37: Adam Grant | D37: 2013 | G37: =COUNTIF(Concepts!$U$2:$U$400,"*"&$A37&"*") -> 0
A38: BK037 | B38: How the World Really Works | C38: Vaclav Smil | G38: =COUNTIF(Concepts!$U$2:$U$400,"*"&$A38&"*") -> 0
A39: BK038 | B39: Ikigai | C39: Héctor García & Francesc Miralles | G39: =COUNTIF(Concepts!$U$2:$U$400,"*"&$A39&"*") -> 0
A40: BK039 | B40: Influence | C40: Robert B. Cialdini | G40: =COUNTIF(Concepts!$U$2:$U$400,"*"&$A40&"*") -> 0
...

Sheet Identities
A1: Identity | B1: The claim they earn | C1: Folds in | D1: Integration | E1: Discovery | F1: Total | G1: Share of library
A2: Clear thinker | B2: I am a critical thinker | C2: Understands complex ideas; sharp memory | D2: =COUNTIFS(Concepts!$S$2:$S$400,"*"&$A2&"*",Concepts!$D$2:$D$400,"Integration") -> 0 | E2: =COUNTIFS(Concepts!$S$2:$S$400,"*"&$A2&"*",Concepts!$D$2:$D$400,"Discovery") -> 0 | F2: =D2+E2 -> 0 | G2: =IFERROR($F2/COUNTA(Concepts!$C$2:$C$400),0) -> 0
A3: Disciplined | B3: I am disciplined and consistent | C3: Consistency; intentional with my time; habits build my life | D3: =COUNTIFS(Concepts!$S$2:$S$400,"*"&$A3&"*",Concepts!$D$2:$D$400,"Integration") -> 0 | E3: =COUNTIFS(Concepts!$S$2:$S$400,"*"&$A3&"*",Concepts!$D$2:$D$400,"Discovery") -> 0 | F3: =D3+E3 -> 0 | G3: =IFERROR($F3/COUNTA(Concepts!$C$2:$C$400),0) -> 0
A4: Clear communicator | B4: I am a clear communicator | C4: Concise; storytelling; writing; debating | D4: =COUNTIFS(Concepts!$S$2:$S$400,"*"&$A4&"*",Concepts!$D$2:$D$400,"Integration") -> 0 | E4: =COUNTIFS(Concepts!$S$2:$S$400,"*"&$A4&"*",Concepts!$D$2:$D$400,"Discovery") -> 0 | F4: =D4+E4 -> 0 | G4: =IFERROR($F4/COUNTA(Concepts!$C$2:$C$400),0) -> 0
A5: Emotionally regulated | B5: I have a calm nervous system | C5: Emotional regulation; not affected by others; positive self-dialogue | D5: =COUNTIFS(Concepts!$S$2:$S$400,"*"&$A5&"*",Concepts!$D$2:$D$400,"Integration") -> 0 | E5: =COUNTIFS(Concepts!$S$2:$S$400,"*"&$A5&"*",Concepts!$D$2:$D$400,"Discovery") -> 0 | F5: =D5+E5 -> 0 | G5: =IFERROR($F5/COUNTA(Concepts!$C$2:$C$400),0) -> 0
A6: Manipulation proof | B6: I understand human nature | C6: Reads behaviour; resists influence | D6: =COUNTIFS(Concepts!$S$2:$S$400,"*"&$A6&"*",Concepts!$D$2:$D$400,"Integration") -> 0 | E6: =COUNTIFS(Concepts!$S$2:$S$400,"*"&$A6&"*",Concepts!$D$2:$D$400,"Discovery") -> 0 | F6: =D6+E6 -> 0 | G6: =IFERROR($F6/COUNTA(Concepts!$C$2:$C$400),0) -> 0
A7: High integrity | B7: I have integrity with myself and others | C7: Grace with boundaries | D7: =COUNTIFS(Concepts!$S$2:$S$400,"*"&$A7&"*",Concepts!$D$2:$D$400,"Integration") -> 0 | E7: =COUNTIFS(Concepts!$S$2:$S$400,"*"&$A7&"*",Concepts!$D$2:$D$400,"Discovery") -> 0 | F7: =D7+E7 -> 0 | G7: =IFERROR($F7/COUNTA(Concepts!$C$2:$C$400),0) -> 0
A8: Creatively unblocked | B8: I make creativity a priority | C8: No creative blocks | D8: =COUNTIFS(Concepts!$S$2:$S$400,"*"&$A8&"*",Concepts!$D$2:$D$400,"Integration") -> 0 | E8: =COUNTIFS(Concepts!$S$2:$S$400,"*"&$A8&"*",Concepts!$D$2:$D$400,"Discovery") -> 0 | F8: =D8+E8 -> 0 | G8: =IFERROR($F8/COUNTA(Concepts!$C$2:$C$400),0) -> 0
A9: Self-authoring | B9: I don't let my past define my future | C9: Stops self-sabotage | D9: =COUNTIFS(Concepts!$S$2:$S$400,"*"&$A9&"*",Concepts!$D$2:$D$400,"Integration") -> 0 | E9: =COUNTIFS(Concepts!$S$2:$S$400,"*"&$A9&"*",Concepts!$D$2:$D$400,"Discovery") -> 0 | F9: =D9+E9 -> 0 | G9: =IFERROR($F9/COUNTA(Concepts!$C$2:$C$400),0) -> 0
A10: Sound judgement | B10: I decide well under uncertainty | C10: Weighs risk; resists the biases that distort choosing; knows what a number does and does not tell them | D10: =COUNTIFS(Concepts!$T$2:$T$600,"*"&$A10&"*",Concepts!$D$2:$D$600,"Integration") -> 0 | E10: =COUNTIFS(Concepts!$T$2:$T$600,"*"&$A10&"*",Concepts!$D$2:$D$600,"Discovery") -> 0 | F10: =D10+E10 -> 0 | G10: =IFERROR($F10/COUNTA(Concepts!$C$2:$C$600),0) -> 0
A11: Systems literate | B11: I see why things turn out as they do | C11: Reads incentives, institutions and power; understands why good people can produce bad outcomes | D11: =COUNTIFS(Concepts!$T$2:$T$600,"*"&$A11&"*",Concepts!$D$2:$D$600,"Integration") -> 0 | E11: =COUNTIFS(Concepts!$T$2:$T$600,"*"&$A11&"*",Concepts!$D$2:$D$600,"Discovery") -> 0 | F11: =D11+E11 -> 0 | G11: =IFERROR($F11/COUNTA(Concepts!$C$2:$C$600),0) -> 0
A13: Clear thinker was split in three on 4 October. It had grown to 209 concepts, forty three per cent of the library, which meant a user choosing it got almost half of everything weighted toward them while a user on a thin identity got very little. Reasoning and logic stayed as Clear thinker. Decisions under uncertainty became Sound judgement. Incentives, institutions and power became Systems literate. Integration concepts are the expensive ones, because they need a Praxis Exercise written. Discovery concepts are roughly half the work. Watch the Share column as the library grows: if one identity drifts far above the others, users who pick it get a weighted wheel full of material while users on a thin identity get very little. A first slice is a COUNT you choose (say 15 concepts), not a whole identity. Nothing is tagged yet unless you have tagged it, and until a concept carries a tag it can never be surfaced by a goal or weight the wheel. Cut deliberately: 'high self confidence & self worth' names a feeling, not a practice. There is no instance of it a user can log. Test for anything added: can a user point to a specific thing they did, on a specific day, that counts as evidence? Spelling must match the Vocabulary sheet exactly, because matching is literal and a typo fails silently.

Sheet Authoring Guide
A1: PRAXIS concept library
A2: Seeded from the 300 concepts already live on the site. Every row starts as a Stub.
A4: Progress
A5: Concepts in library | B5: =COUNTA(Concepts!$C$2:$C$400) -> 399
A6: Done | B6: =COUNTIF(Concepts!$A$2:$A$400,"Done") -> 60
A7: Drafted or in review | B7: =COUNTIF(Concepts!$A$2:$A$400,"Drafted")+COUNTIF(Concepts!$A$2:$A$400,"In review") -> 0
A8: Still a stub | B8: =COUNTIF(Concepts!$A$2:$A$400,"Stub") -> 339
A9: Tagged to an identity | B9: =COUNTIF(Concepts!$S$2:$S$400,"?*") -> 60
A10: Tier assigned | B10: =COUNTIF(Concepts!$D$2:$D$400,"?*") -> 399
A11: Books in library | B11: =COUNTA(Books!$B$2:$B$300) -> 138
A13: Where to start
A14: Do not author breadth-first | B14: 300 concepts at full depth is well over a hundred hours. Pick ONE identity, complete every concept under it, and you have a shippable vertical slice: a goal a user can set, a weighted wheel, enough scenarios to interleave against.
A15: Step one | B15: Assign Tier and Identity Tags across all 300. Fast, mechanical, and it tells you how big each vertical slice actually is before you commit to one.
A16: Step two | B16: Filter to your chosen identity and author those rows to Done.
A18: The tier test
A19: One question | B19: Can you write an honest if-then commitment for this concept? If yes it is Integration tier and needs a Praxis Exercise. If no it is Discovery tier and must not have one.
A20: Why it matters | B20: Forcing a protocol onto a concept that has none is how a library fills with self-help sludge. Plenty of your Myth, Symbol & Spiritual Traditions entries are Discovery tier, and that is correct.
A22: Field standards
A23: Evidence | B23: How far a reader should trust this as a claim about the world. Replicated, Supported, Contested, Framework, Philosophical or Traditional, spelled exactly as on the Vocabulary sheet. Most of the library is Framework or Philosophical and that is fine. Contested is for ideas that are taught everywhere and whose evidence is genuinely disputed, and the card says so out loud. The export refuses a finished concept with this left blank.
A24: One Sentence | B24: Under 20 words, no jargon. Also the hook line for short-form video, so it has to land spoken aloud.
A25: Story | B25: Optional, and the whole point of a myth. Where a concept arrives as a narrative, tell the narrative here in 150 to 220 words, in paragraphs separated by a blank line, and the site gives it a reading screen of its own before any question. Tell it, do not summarise it: the concrete details are what make it stick. Required for anything typed Mythic Concept or Archetype, and the export refuses those without one. Also worth filling for concepts that are really stories, such as Ship of Theseus, the Trolley Problem and Solomon's Paradox.
A26: Definition | B26: 3-5 sentences. The canonical version, including origin where it sharpens meaning.
A27: Mechanism | B27: Write as an ORDERED CHAIN with -> arrows, not a paragraph. Map It is generated by splitting at the arrows, so prose here means no exercise.
A28: Common Misconception | B28: The degraded internet version stated plainly, then what is wrong with it. Feeds the Distinguish rung, the Teach It rubric and the video hook.
A29: Nearest Neighbour | B29: Start with the concept's name in CAPITALS followed by a full stop, then the real difference. The site rewrites that opening into a sentence, so a comma inside the capitalised name breaks it. Supplies the hardest distractor free.
A30: Discriminate Scenario | B30: 40-70 words. A situation where the concept operates, never naming it. Becomes the Spot rung and joins the shared interleaving pool.
A31: Praxis Exercise | B31: Integration tier only. Recognise -> Use -> Act, ending in an if-then commitment with a verb and a timeframe.
A32: Identity Tags | B32: 1-3 from the Identities sheet, semicolon separated, spelled exactly.
A33: Related Concepts | B33: Semicolon separated, by Praxis ID or Canonical Name. Write the link once from either side and the export mirrors it.
A34: Book IDs | B34: Semicolon separated, from the Books sheet. Never a title. Pre-filled from the live site's reference lists.
A36: Publishing
A37: The loop | B37: Edit in Google Sheets -> download as .xlsx -> upload into content/ on GitHub -> the Export content library workflow runs itself -> publish from GoDaddy.
A38: It will refuse | B38: if a Done row is missing a required field for its tier, a Domain or Type is off-vocabulary, an Identity Tag is misspelled, a Book ID does not exist, a Discovery row carries an exercise, or a Discriminate Scenario names its own concept.
A39: Only Done rows ship | B39: Stubs and drafts never reach the site, so you can author in the open.
